Workbook

Sheet 0. Notes
A2: The Sheet 'Frailty_inputs_do_not_edit' should be saved as csv for reading by the Stella model
A3: It should not be edited except when you want to change the structure of inputs - e.g., add or remove an input.
A4: The other tabs have the editable inputs. If you want to change values, make the changes here and then save Tab 1 as a csv

Sheet 1. Frailty_inputs_do_not_edit
A1: =_xlfn.CONCAT('2 Resident Population'!B1,".",'2 Resident Population'!A4) -> Resident Population.age-specific baseline mortality rate[male, age] | B1: ='2 Resident Population'!B4 -> 1.99375 | C1: ='2 Resident Population'!C4 -> 1.99375 | D1: ='2 Resident Population'!D4 -> 0.14375 | E1: ='2 Resident Population'!E4 -> 0.14375 | F1: ='2 Resident Population'!F4 -> 0.14375 | G1: ='2 Resident Population'!G4 -> 0.14375 | H1: ='2 Resident Population'!H4 -> 0.1 | I1: ='2 Resident Population'!I4 -> 0.1 | ... CY1: ='2 Resident Population'!CY4 -> 173.4125
A2: =_xlfn.CONCAT('2 Resident Population'!B1,".",'2 Resident Population'!A5) -> Resident Population.age-specific baseline mortality rate[female, age] | B2: ='2 Resident Population'!B5 -> 1.9375 | C2: ='2 Resident Population'!C5 -> 1.9375 | D2: ='2 Resident Population'!D5 -> 0.11333333 | E2: ='2 Resident Population'!E5 -> 0.11333333 | F2: ='2 Resident Population'!F5 -> 0.11333333 | G2: ='2 Resident Population'!G5 -> 0.11333333 | H2: ='2 Resident Population'!H5 -> 0.1 | I2: ='2 Resident Population'!I5 -> 0.1 | ... CY2: ='2 Resident Population'!CY5 -> 154.11875
A3: =_xlfn.CONCAT('2 Resident Population'!B1,".",'2 Resident Population'!A8) -> Resident Population.fertility rate[age] | B3: ='2 Resident Population'!B8 -> 0 | C3: ='2 Resident Population'!C8 -> 0 | D3: ='2 Resident Population'!D8 -> 0 | E3: ='2 Resident Population'!E8 -> 0 | F3: ='2 Resident Population'!F8 -> 0 | G3: ='2 Resident Population'!G8 -> 0 | H3: ='2 Resident Population'!H8 -> 0 | I3: ='2 Resident Population'!I8 -> 0 | ... CY3: ='2 Resident Population'!CY8 -> 0
A4: =_xlfn.CONCAT('2 Resident Population'!B1,".",'2 Resident Population'!A11) -> Resident Population.gender proportion of babies[gender] | B4: ='2 Resident Population'!B11 -> 0.48 | C4: ='2 Resident Population'!C11 -> 0.52
A5: =_xlfn.CONCAT('2 Resident Population'!B1,".",'2 Resident Population'!A14) -> Resident Population.resident population[Chinese, male, age] | B5: ='2 Resident Population'!B14 -> 0 | C5: ='2 Resident Population'!C14 -> 11690 | D5: ='2 Resident Population'!D14 -> 13107 | E5: ='2 Resident Population'!E14 -> 13950 | F5: ='2 Resident Population'!F14 -> 13455 | G5: ='2 Resident Population'!G14 -> 13487 | H5: ='2 Resident Population'!H14 -> 13571 | I5: ='2 Resident Population'!I14 -> 13356 | ... CY5: ='2 Resident Population'!CY14 -> 203
A6: =_xlfn.CONCAT('2 Resident Population'!B1,".",'2 Resident Population'!A15) -> Resident Population.resident population[Chinese, female, age] | B6: ='2 Resident Population'!B15 -> 0 | C6: ='2 Resident Population'!C15 -> 11185 | D6: ='2 Resident Population'!D15 -> 12384 | E6: ='2 Resident Population'!E15 -> 13323 | F6: ='2 Resident Population'!F15 -> 12864 | G6: ='2 Resident Population'!G15 -> 12868 | H6: ='2 Resident Population'!H15 -> 13017 | I6: ='2 Resident Population'!I15 -> 12598 | ... CY6: ='2 Resident Population'!CY15 -> 446
A7: =_xlfn.CONCAT('2 Resident Population'!B1,".",'2 Resident Population'!A16) -> Resident Population.resident population[Malay, male, age] | B7: ='2 Resident Population'!B16 -> 0 | C7: ='2 Resident Population'!C16 -> 3016 | D7: ='2 Resident Population'!D16 -> 3261 | E7: ='2 Resident Population'!E16 -> 3308 | F7: ='2 Resident Population'!F16 -> 3458 | G7: ='2 Resident Population'!G16 -> 3453 | H7: ='2 Resident Population'!H16 -> 3440 | I7: ='2 Resident Population'!I16 -> 3484 | ... CY7: ='2 Resident Population'!CY16 -> 12
A8: =_xlfn.CONCAT('2 Resident Population'!B1,".",'2 Resident Population'!A17) -> Resident Population.resident population[Malay, female, age] | B8: ='2 Resident Population'!B17 -> 0 | C8: ='2 Resident Population'!C17 -> 2906 | D8: ='2 Resident Population'!D17 -> 3096 | E8: ='2 Resident Population'!E17 -> 3260 | F8: ='2 Resident Population'!F17 -> 3159 | G8: ='2 Resident Population'!G17 -> 3286 | H8: ='2 Resident Population'!H17 -> 3233 | I8: ='2 Resident Population'!I17 -> 3416 | ... CY8: ='2 Resident Population'!CY17 -> 10
A9: =_xlfn.CONCAT('2 Resident Population'!B1,".",'2 Resident Population'!A18) -> Resident Population.resident population[Indian, male, age] | B9: ='2 Resident Population'!B18 -> 0 | C9: ='2 Resident Population'!C18 -> 1447 | D9: ='2 Resident Population'!D18 -> 2236 | E9: ='2 Resident Population'!E18 -> 2739 | F9: ='2 Resident Population'!F18 -> 2874 | G9: ='2 Resident Population'!G18 -> 2820 | H9: ='2 Resident Population'!H18 -> 2698 | I9: ='2 Resident Population'!I18 -> 2782 | ... CY9: ='2 Resident Population'!CY18 -> 37
A10: =_xlfn.CONCAT('2 Resident Population'!B1,".",'2 Resident Population'!A19) -> Resident Population.resident population[Indian, female, age] | B10: ='2 Resident Population'!B19 -> 0 | C10: ='2 Resident Population'!C19 -> 1480 | D10: ='2 Resident Population'!D19 -> 2274 | E10: ='2 Resident Population'!E19 -> 2812 | F10: ='2 Resident Population'!F19 -> 2888 | G10: ='2 Resident Population'!G19 -> 2855 | H10: ='2 Resident Population'!H19 -> 2812 | I10: ='2 Resident Population'!I19 -> 2697 | ... CY10: ='2 Resident Population'!CY19 -> 7
A11: =_xlfn.CONCAT('2 Resident Population'!B1,".",'2 Resident Population'!A20) -> Resident Population.resident population[Other, male, age] | B11: ='2 Resident Population'!B20 -> 0 | C11: ='2 Resident Population'!C20 -> 540 | D11: ='2 Resident Population'!D20 -> 945 | E11: ='2 Resident Population'!E20 -> 1052 | F11: ='2 Resident Population'!F20 -> 1066 | G11: ='2 Resident Population'!G20 -> 986 | H11: ='2 Resident Population'!H20 -> 1046 | I11: ='2 Resident Population'!I20 -> 1076 | ... CY11: ='2 Resident Population'!CY20 -> 6
A12: =_xlfn.CONCAT('2 Resident Population'!B1,".",'2 Resident Population'!A21) -> Resident Population.resident population[Other, female, age] | B12: ='2 Resident Population'!B21 -> 0 | C12: ='2 Resident Population'!C21 -> 524 | D12: ='2 Resident Population'!D21 -> 1047 | E12: ='2 Resident Population'!E21 -> 1118 | F12: ='2 Resident Population'!F21 -> 1105 | G12: ='2 Resident Population'!G21 -> 1108 | H12: ='2 Resident Population'!H21 -> 1098 | I12: ='2 Resident Population'!I21 -> 1063 | ... CY12: ='2 Resident Population'!CY21 -> 3
A13: =_xlfn.CONCAT('2 Resident Population'!B1,".",'2 Resident Population'!A24) -> Resident Population.net migration rate[Chinese, male, age] | B13: ='2 Resident Population'!B24 -> 0 | C13: ='2 Resident Population'!C24 -> 0.0059 | D13: ='2 Resident Population'!D24 -> 0.0059 | E13: ='2 Resident Population'!E24 -> 0.0059 | F13: ='2 Resident Population'!F24 -> 0.0059 | G13: ='2 Resident Population'!G24 -> 0.0059 | H13: ='2 Resident Population'!H24 -> 0.0059 | I13: ='2 Resident Population'!I24 -> 0.0059 | ... CY13: ='2 Resident Population'!CY24 -> 0
A14: =_xlfn.CONCAT('2 Resident Population'!B1,".",'2 Resident Population'!A25) -> Resident Population.net migration rate[Chinese, female, age] | B14: ='2 Resident Population'!B25 -> 0 | C14: ='2 Resident Population'!C25 -> 0.0059 | D14: ='2 Resident Population'!D25 -> 0.0059 | E14: ='2 Resident Population'!E25 -> 0.0059 | F14: ='2 Resident Population'!F25 -> 0.0059 | G14: ='2 Resident Population'!G25 -> 0.0059 | H14: ='2 Resident Population'!H25 -> 0.0059 | I14: ='2 Resident Population'!I25 -> 0.0059 | ... CY14: ='2 Resident Population'!CY25 -> 0
A15: =_xlfn.CONCAT('2 Resident Population'!B1,".",'2 Resident Population'!A26) -> Resident Population.net migration rate[Malay, male, age] | B15: ='2 Resident Population'!B26 -> 0 | C15: ='2 Resident Population'!C26 -> 0.0059 | D15: ='2 Resident Population'!D26 -> 0.0059 | E15: ='2 Resident Population'!E26 -> 0.0059 | F15: ='2 Resident Population'!F26 -> 0.0059 | G15: ='2 Resident Population'!G26 -> 0.0059 | H15: ='2 Resident Population'!H26 -> 0.0059 | I15: ='2 Resident Population'!I26 -> 0.0059 | ... CY15: ='2 Resident Population'!CY26 -> 0
A16: =_xlfn.CONCAT('2 Resident Population'!B1,".",'2 Resident Population'!A27) -> Resident Population.net migration rate[Malay, female, age] | B16: ='2 Resident Population'!B27 -> 0 | C16: ='2 Resident Population'!C27 -> 0.0059 | D16: ='2 Resident Population'!D27 -> 0.0059 | E16: ='2 Resident Population'!E27 -> 0.0059 | F16: ='2 Resident Population'!F27 -> 0.0059 | G16: ='2 Resident Population'!G27 -> 0.0059 | H16: ='2 Resident Population'!H27 -> 0.0059 | I16: ='2 Resident Population'!I27 -> 0.0059 | ... CY16: ='2 Resident Population'!CY27 -> 0
A17: =_xlfn.CONCAT('2 Resident Population'!B1,".",'2 Resident Population'!A28) -> Resident Population.net migration rate[Indian, male, age] | B17: ='2 Resident Population'!B28 -> 0 | C17: ='2 Resident Population'!C28 -> 0.0059 | D17: ='2 Resident Population'!D28 -> 0.0059 | E17: ='2 Resident Population'!E28 -> 0.0059 | F17: ='2 Resident Population'!F28 -> 0.0059 | G17: ='2 Resident Population'!G28 -> 0.0059 | H17: ='2 Resident Population'!H28 -> 0.0059 | I17: ='2 Resident Population'!I28 -> 0.0059 | ... CY17: ='2 Resident Population'!CY28 -> 0
A18: =_xlfn.CONCAT('2 Resident Population'!B1,".",'2 Resident Population'!A29) -> Resident Population.net migration rate[Indian, female, age] | B18: ='2 Resident Population'!B29 -> 0 | C18: ='2 Resident Population'!C29 -> 0.0059 | D18: ='2 Resident Population'!D29 -> 0.0059 | E18: ='2 Resident Population'!E29 -> 0.0059 | F18: ='2 Resident Population'!F29 -> 0.0059 | G18: ='2 Resident Population'!G29 -> 0.0059 | H18: ='2 Resident Population'!H29 -> 0.0059 | I18: ='2 Resident Population'!I29 -> 0.0059 | ... CY18: ='2 Resident Population'!CY29 -> 0
A19: =_xlfn.CONCAT('2 Resident Population'!B1,".",'2 Resident Population'!A30) -> Resident Population.net migration rate[Other, male, age] | B19: ='2 Resident Population'!B30 -> 0 | C19: ='2 Resident Population'!C30 -> 0.0059 | D19: ='2 Resident Population'!D30 -> 0.0059 | E19: ='2 Resident Population'!E30 -> 0.0059 | F19: ='2 Resident Population'!F30 -> 0.0059 | G19: ='2 Resident Population'!G30 -> 0.0059 | H19: ='2 Resident Population'!H30 -> 0.0059 | I19: ='2 Resident Population'!I30 -> 0.0059 | ... CY19: ='2 Resident Population'!CY30 -> 0
A20: =_xlfn.CONCAT('2 Resident Population'!B1,".",'2 Resident Population'!A31) -> Resident Population.net migration rate[Other, female, age] | B20: ='2 Resident Population'!B31 -> 0 | C20: ='2 Resident Population'!C31 -> 0.0059 | D20: ='2 Resident Population'!D31 -> 0.0059 | E20: ='2 Resident Population'!E31 -> 0.0059 | F20: ='2 Resident Population'!F31 -> 0.0059 | G20: ='2 Resident Population'!G31 -> 0.0059 | H20: ='2 Resident Population'!H31 -> 0.0059 | I20: ='2 Resident Population'!I31 -> 0.0059 | ... CY20: ='2 Resident Population'!CY31 -> 0
A21: ='3. Frail population'!A3 -> Frail Population.age as a number[age] | B21: ='3. Frail population'!B3 -> 0 | C21: ='3. Frail population'!C3 -> 0 | D21: ='3. Frail population'!D3 -> 1 | E21: ='3. Frail population'!E3 -> 2 | F21: ='3. Frail population'!F3 -> 3 | G21: ='3. Frail population'!G3 -> 4 | H21: ='3. Frail population'!H3 -> 5 | ... CY21: ='3. Frail population'!CY3 -> 100
A22: ='3. Frail population'!A6 -> Frail Population.frail diagnosed[Chinese, male, age] | B22: ='3. Frail population'!B6 -> 0 | C22: ='3. Frail population'!C6 -> 0 | D22: ='3. Frail population'!D6 -> 0 | E22: ='3. Frail population'!E6 -> 0 | F22: ='3. Frail population'!F6 -> 0 | G22: ='3. Frail population'!G6 -> 0 | H22: ='3. Frail population'!H6 -> 0 | ... CY22: ='3. Frail population'!CY6 -> 0
A23: ='3. Frail population'!A7 -> Frail Population.frail diagnosed[Chinese, female, age] | B23: ='3. Frail population'!B7 -> 0 | C23: ='3. Frail population'!C7 -> 0 | D23: ='3. Frail population'!D7 -> 0 | E23: ='3. Frail population'!E7 -> 0 | F23: ='3. Frail population'!F7 -> 0 | G23: ='3. Frail population'!G7 -> 0 | H23: ='3. Frail population'!H7 -> 0 | ... CY23: ='3. Frail population'!CY7 -> 0
A24: ='3. Frail population'!A8 -> Frail Population.frail diagnosed[Malay, male, age] | B24: ='3. Frail population'!B8 -> 0 | C24: ='3. Frail population'!C8 -> 0 | D24: ='3. Frail population'!D8 -> 0 | E24: ='3. Frail population'!E8 -> 0 | F24: ='3. Frail population'!F8 -> 0 | G24: ='3. Frail population'!G8 -> 0 | H24: ='3. Frail population'!H8 -> 0 | ... CY24: ='3. Frail population'!CY8 -> 0
A25: ='3. Frail population'!A9 -> Frail Population.frail diagnosed[Malay, female, age] | B25: ='3. Frail population'!B9 -> 0 | C25: ='3. Frail population'!C9 -> 0 | D25: ='3. Frail population'!D9 -> 0 | E25: ='3. Frail population'!E9 -> 0 | F25: ='3. Frail population'!F9 -> 0 | G25: ='3. Frail population'!G9 -> 0 | H25: ='3. Frail population'!H9 -> 0 | ... CY25: ='3. Frail population'!CY9 -> 0
A26: ='3. Frail population'!A10 -> Frail Population.frail diagnosed[Indian, male, age] | B26: ='3. Frail population'!B10 -> 0 | C26: ='3. Frail population'!C10 -> 0 | D26: ='3. Frail population'!D10 -> 0 | E26: ='3. Frail population'!E10 -> 0 | F26: ='3. Frail population'!F10 -> 0 | G26: ='3. Frail population'!G10 -> 0 | H26: ='3. Frail population'!H10 -> 0 | ... CY26: ='3. Frail population'!CY10 -> 0
A27: ='3. Frail population'!A11 -> Frail Population.frail diagnosed[Indian, female, age] | B27: ='3. Frail population'!B11 -> 0 | C27: ='3. Frail population'!C11 -> 0 | D27: ='3. Frail population'!D11 -> 0 | E27: ='3. Frail population'!E11 -> 0 | F27: ='3. Frail population'!F11 -> 0 | G27: ='3. Frail population'!G11 -> 0 | H27: ='3. Frail population'!H11 -> 0 | ... CY27: ='3. Frail population'!CY11 -> 0
A28: ='3. Frail population'!A12 -> Frail Population.frail diagnosed[Other, male, age] | B28: ='3. Frail population'!B12 -> 0 | C28: ='3. Frail population'!C12 -> 0 | D28: ='3. Frail population'!D12 -> 0 | E28: ='3. Frail population'!E12 -> 0 | F28: ='3. Frail population'!F12 -> 0 | G28: ='3. Frail population'!G12 -> 0 | H28: ='3. Frail population'!H12 -> 0 | ... CY28: ='3. Frail population'!CY12 -> 0
A29: ='3. Frail population'!A13 -> Frail Population.frail diagnosed[Other, female, age] | B29: ='3. Frail population'!B13 -> 0 | C29: ='3. Frail population'!C13 -> 0 | D29: ='3. Frail population'!D13 -> 0 | E29: ='3. Frail population'!E13 -> 0 | F29: ='3. Frail population'!F13 -> 0 | G29: ='3. Frail population'!G13 -> 0 | H29: ='3. Frail population'!H13 -> 0 | ... CY29: ='3. Frail population'!CY13 -> 0
A30: ='3. Frail population'!A14 -> Frail Population.pre-frail diagnosed[Chinese, male, age] | B30: ='3. Frail population'!B14 -> 0 | C30: ='3. Frail population'!C14 -> 0 | D30: ='3. Frail population'!D14 -> 0 | E30: ='3. Frail population'!E14 -> 0 | F30: ='3. Frail population'!F14 -> 0 | G30: ='3. Frail population'!G14 -> 0 | H30: ='3. Frail population'!H14 -> 0 | ... CY30: ='3. Frail population'!CY14 -> 0
A31: ='3. Frail population'!A15 -> Frail Population.pre-frail diagnosed[Chinese, female, age] | B31: ='3. Frail population'!B15 -> 0 | C31: ='3. Frail population'!C15 -> 0 | D31: ='3. Frail population'!D15 -> 0 | E31: ='3. Frail population'!E15 -> 0 | F31: ='3. Frail population'!F15 -> 0 | G31: ='3. Frail population'!G15 -> 0 | H31: ='3. Frail population'!H15 -> 0 | ... CY31: ='3. Frail population'!CY15 -> 0
A32: ='3. Frail population'!A16 -> Frail Population.pre-frail diagnosed[Malay, male, age] | B32: ='3. Frail population'!B16 -> 0 | C32: ='3. Frail population'!C16 -> 0 | D32: ='3. Frail population'!D16 -> 0 | E32: ='3. Frail population'!E16 -> 0 | F32: ='3. Frail population'!F16 -> 0 | G32: ='3. Frail population'!G16 -> 0 | H32: ='3. Frail population'!H16 -> 0 | ... CY32: ='3. Frail population'!CY16 -> 0
A33: ='3. Frail population'!A17 -> Frail Population.pre-frail diagnosed[Malay, female, age] | B33: ='3. Frail population'!B17 -> 0 | C33: ='3. Frail population'!C17 -> 0 | D33: ='3. Frail population'!D17 -> 0 | E33: ='3. Frail population'!E17 -> 0 | F33: ='3. Frail population'!F17 -> 0 | G33: ='3. Frail population'!G17 -> 0 | H33: ='3. Frail population'!H17 -> 0 | ... CY33: ='3. Frail population'!CY17 -> 0
... A37: ='3. Frail population'!A21 -> Frail Population.pre-frail diagnosed[Other, female, age] | B37: ='3. Frail population'!B21 -> 0 | C37: ='3. Frail population'!C21 -> 0 | D37: ='3. Frail population'!D21 -> 0 | E37: ='3. Frail population'!E21 -> 0 | F37: ='3. Frail population'!F21 -> 0 | G37: ='3. Frail population'!G21 -> 0 | H37: ='3. Frail population'!H21 -> 0 | ... CY37: ='3. Frail population'!CY21 -> 0
A38: ='3. Frail population'!A24 -> Frail Population.initial frailty prevalence[Chinese, male, age] | B38: ='3. Frail population'!B24 -> 0 | C38: ='3. Frail population'!C24 -> 0 | D38: ='3. Frail population'!D24 -> 0 | E38: ='3. Frail population'!E24 -> 0 | F38: ='3. Frail population'!F24 -> 0 | G38: ='3. Frail population'!G24 -> 0 | H38: ='3. Frail population'!H24 -> 0 | ... CY38: ='3. Frail population'!CY24 -> 0.25780987
A39: ='3. Frail population'!A25 -> Frail Population.initial frailty prevalence[Chinese, female, age] | B39: ='3. Frail population'!B25 -> 0 | C39: ='3. Frail population'!C25 -> 0 | D39: ='3. Frail population'!D25 -> 0 | E39: ='3. Frail population'!E25 -> 0 | F39: ='3. Frail population'!F25 -> 0 | G39: ='3. Frail population'!G25 -> 0 | H39: ='3. Frail population'!H25 -> 0 | ... CY39: ='3. Frail population'!CY25 -> 0.25222712
A40: ='3. Frail population'!A26 -> Frail Population.initial frailty prevalence[Malay, male, age] | B40: ='3. Frail population'!B26 -> 0 | C40: ='3. Frail population'!C26 -> 0 | D40: ='3. Frail population'!D26 -> 0 | E40: ='3. Frail population'!E26 -> 0 | F40: ='3. Frail population'!F26 -> 0 | G40: ='3. Frail population'!G26 -> 0 | H40: ='3. Frail population'!H26 -> 0 | ... CY40: ='3. Frail population'!CY26 -> 0.27895342
A41: ='3. Frail population'!A27 -> Frail Population.initial frailty prevalence[Malay, female, age] | B41: ='3. Frail population'!B27 -> 0 | C41: ='3. Frail population'!C27 -> 0 | D41: ='3. Frail population'!D27 -> 0 | E41: ='3. Frail population'!E27 -> 0 | F41: ='3. Frail population'!F27 -> 0 | G41: ='3. Frail population'!G27 -> 0 | H41: ='3. Frail population'!H27 -> 0 | ... CY41: ='3. Frail population'!CY27 -> 0.26823531
A42: ='3. Frail population'!A28 -> Frail Population.initial frailty prevalence[Indian, male, age] | B42: ='3. Frail population'!B28 -> 0 | C42: ='3. Frail population'!C28 -> 0 | D42: ='3. Frail population'!D28 -> 0 | E42: ='3. Frail population'!E28 -> 0 | F42: ='3. Frail population'!F28 -> 0 | G42: ='3. Frail population'!G28 -> 0 | H42: ='3. Frail population'!H28 -> 0 | ... CY42: ='3. Frail population'!CY28 -> 0.28611671
A43: ='3. Frail population'!A29 -> Frail Population.initial frailty prevalence[Indian, female, age] | B43: ='3. Frail population'!B29 -> 0 | C43: ='3. Frail population'!C29 -> 0 | D43: ='3. Frail population'!D29 -> 0 | E43: ='3. Frail population'!E29 -> 0 | F43: ='3. Frail population'!F29 -> 0 | G43: ='3. Frail population'!G29 -> 0 | H43: ='3. Frail population'!H29 -> 0 | ... CY43: ='3. Frail population'!CY29 -> 0.27730361
...

Sheet 2. Time_series_do_not_edit
A1: ='2 Resident Population'!A38 -> Time | B1: ='2 Resident Population'!B38 -> 2010 | C1: ='2 Resident Population'!C38 -> 2011 | D1: ='2 Resident Population'!D38 -> 2012 | E1: ='2 Resident Population'!E38 -> 2013 | F1: ='2 Resident Population'!F38 -> 2014 | G1: ='2 Resident Population'!G38 -> 2015 | H1: ='2 Resident Population'!H38 -> 2016 | ... AP1: ='2 Resident Population'!AP38 -> 2050
A2: ='2 Resident Population'!A39 -> Resident Population.census total resident population | B2: ='2 Resident Population'!B39 -> 3771721 | C2: ='2 Resident Population'!C39 -> 3789251 | D2: ='2 Resident Population'!D39 -> 3818205 | E2: ='2 Resident Population'!E39 -> 3844751 | F2: ='2 Resident Population'!F39 -> 3870739 | G2: ='2 Resident Population'!G39 -> 3902690 | H2: ='2 Resident Population'!H39 -> 3933559 | ... AF2: ='2 Resident Population'!AF39 -> 4422600 | AG2: 0 | AH2: 0 | AI2: ='2 Resident Population'!AI39 -> 0 | AJ2: ='2 Resident Population'!AJ39 -> 0 | AK2: ='2 Resident Population'!AK39 -> 0 | AL2: ='2 Resident Population'!AL39 -> 0 | AM2: ='2 Resident Population'!AM39 -> 0 | AN2: ='2 Resident Population'!AN39 -> 0 | AO2: ='2 Resident Population'!AO39 -> 0 | AP2: ='2 Resident Population'!AP39 -> 0
A3: ='2 Resident Population'!A40 -> Resident Population.census males per thousand females | B3: ='2 Resident Population'!B40 -> 974 | C3: ='2 Resident Population'!C40 -> 972 | D3: ='2 Resident Population'!D40 -> 970 | E3: ='2 Resident Population'!E40 -> 968 | F3: ='2 Resident Population'!F40 -> 967 | G3: ='2 Resident Population'!G40 -> 965 | H3: ='2 Resident Population'!H40 -> 963 | ... AP3: ='2 Resident Population'!AP40 -> 0
A4: ='2 Resident Population'!A41 -> Resident Population.census OADR | B4: ='2 Resident Population'!B41 -> 8.2 | C4: ='2 Resident Population'!C41 -> 7.9 | D4: ='2 Resident Population'!D41 -> 7.4 | E4: ='2 Resident Population'!E41 -> 7 | F4: ='2 Resident Population'!F41 -> 6.6 | G4: ='2 Resident Population'!G41 -> 6.2 | H4: ='2 Resident Population'!H41 -> 5.8 | ... AP4: ='2 Resident Population'!AP41 -> 0

Sheet 2 Resident Population
A1: Module name | B1: Resident Population
A2: ASMR and fertility rates are per 1000
B3: NewBorn | C3: Age00 | D3: Age01 | E3: Age02 | F3: Age03 | G3: Age04 | H3: Age05 | I3: Age06 | J3: Age07 | K3: Age08 | L3: Age09 | M3: Age10 | N3: Age11 | O3: Age12 | P3: Age13 | Q3: Age14 | R3: Age15 | S3: Age16 | T3: Age17 | U3: Age18 | V3: Age19 | W3: Age20 | X3: Age21 | Y3: Age22 | Z3: Age23 | AA3: Age24 | AB3: Age25 | AC3: Age26 | AD3: Age27 | AE3: Age28 | AF3: Age29 | AG3: Age30 | AH3: Age31 | AI3: Age32 | AJ3: Age33 | AK3: Age34 | AL3: Age35 | AM3: Age36 | AN3: Age37 | AO3: Age38 | AP3: Age39 | AQ3: Age40 | AR3: Age41 | AS3: Age42 | AT3: Age43 | AU3: Age44 | AV3: Age45 | AW3: Age46 | AX3: Age47 | AY3: Age48 | AZ3: Age49 | BA3: Age50 | BB3: Age51 | BC3: Age52 | BD3: Age53 | BE3: Age54 | BF3: Age55 | BG3: Age56 | BH3: Age57 | BI3: Age58 | BJ3: Age59 | BK3: Age60 | BL3: Age61 | BM3: Age62 | BN3: Age63 | BO3: Age64 | BP3: Age65 | BQ3: Age66 | BR3: Age67 | BS3: Age68 | BT3: Age69 | BU3: Age70 | BV3: Age71 | BW3: Age72 | BX3: Age73 | BY3: Age74 | BZ3: Age75 | CA3: Age76 | CB3: Age77 | CC3: Age78 | CD3: Age79 | CE3: Age80 | CF3: Age81 | CG3: Age82 | CH3: Age83 | CI3: Age84 | CJ3: Age85 | CK3: Age86 | CL3: Age87 | CM3: Age88 | CN3: Age89 | CO3: Age90 | CP3: Age91 | CQ3: Age92 | CR3: Age93 | CS3: Age94 | CT3: Age95 | CU3: Age96 | CV3: Age97 | CW3: Age98 | CX3: Age99 | CY3: Age100and Over
A4: age-specific baseline mortality rate[male, age] | B4: =C4 -> 1.99375 | C4: 1.99375 | D4: 0.14375 | E4: 0.14375 | F4: 0.14375 | G4: 0.14375 | H4: 0.1 | I4: 0.1 | J4: 0.1 | K4: 0.1 | L4: 0.1 | M4: 0.12857143 | N4: 0.12857143 | O4: 0.12857143 | P4: 0.12857143 | Q4: 0.12857143 | R4: 0.24375 | S4: 0.24375 | T4: 0.24375 | U4: 0.24375 | V4: 0.24375 | W4: 0.375 | X4: 0.375 | Y4: 0.375 | Z4: 0.375 | AA4: 0.375 | AB4: 0.38125 | AC4: 0.38125 | AD4: 0.38125 | AE4: 0.38125 | AF4: 0.38125 | AG4: 0.4625 | AH4: 0.4625 | AI4: 0.4625 | AJ4: 0.4625 | AK4: 0.4625 | AL4: 0.65 | AM4: 0.65 | AN4: 0.65 | AO4: 0.65 | AP4: 0.65 | AQ4: 1.075 | AR4: 1.075 | AS4: 1.075 | AT4: 1.075 | AU4: 1.075 | AV4: 1.8125 | AW4: 1.8125 | AX4: 1.8125 | AY4: 1.8125 | AZ4: 1.8125 | BA4: 3.04375 | BB4: 3.04375 | BC4: 3.04375 | BD4: 3.04375 | BE4: 3.04375 | BF4: 5.13125 | BG4: 5.13125 | BH4: 5.13125 | BI4: 5.13125 | BJ4: 5.13125 | BK4: 8.34375 | BL4: 8.34375 | BM4: 8.34375 | BN4: 8.34375 | BO4: 8.34375 | BP4: 13.56875 | BQ4: 13.56875 | BR4: 13.56875 | BS4: 13.56875 | BT4: 13.56875 | BU4: 22.76875 | BV4: 22.76875 | BW4: 22.76875 | BX4: 22.76875 | BY4: 22.76875 | BZ4: 38.46875 | CA4: 38.46875 | CB4: 38.46875 | CC4: 38.46875 | CD4: 38.46875 | CE4: 66.38125 | CF4: 66.38125 | CG4: 66.38125 | CH4: 66.38125 | CI4: 66.38125 | CJ4: 110.475 | CK4: 110.475 | CL4: 110.475 | CM4: 110.475 | CN4: 110.475 | CO4: 173.4125 | CP4: 173.4125 | CQ4: 173.4125 | CR4: 173.4125 | CS4: 173.4125 | CT4: 173.4125 | CU4: 173.4125 | CV4: 173.4125 | CW4: 173.4125 | CX4: 173.4125 | CY4: 173.4125
A5: age-specific baseline mortality rate[female, age] | B5: =C5 -> 1.9375 | C5: 1.9375 | D5: 0.11333333 | E5: 0.11333333 | F5: 0.11333333 | G5: 0.11333333 | H5: 0.1 | I5: 0.1 | J5: 0.1 | K5: 0.1 | L5: 0.1 | M5: 0.1 | N5: 0.1 | O5: 0.1 | P5: 0.1 | Q5: 0.1 | R5: 0.1625 | S5: 0.1625 | T5: 0.1625 | U5: 0.1625 | V5: 0.1625 | W5: 0.175 | X5: 0.175 | Y5: 0.175 | Z5: 0.175 | AA5: 0.175 | AB5: 0.18125 | AC5: 0.18125 | AD5: 0.18125 | AE5: 0.18125 | AF5: 0.18125 | AG5: 0.2625 | AH5: 0.2625 | AI5: 0.2625 | AJ5: 0.2625 | AK5: 0.2625 | AL5: 0.39375 | AM5: 0.39375 | AN5: 0.39375 | AO5: 0.39375 | AP5: 0.39375 | AQ5: 0.63125 | AR5: 0.63125 | AS5: 0.63125 | AT5: 0.63125 | AU5: 0.63125 | AV5: 1.08125 | AW5: 1.08125 | AX5: 1.08125 | AY5: 1.08125 | AZ5: 1.08125 | BA5: 1.80625 | BB5: 1.80625 | BC5: 1.80625 | BD5: 1.80625 | BE5: 1.80625 | BF5: 2.85625 | BG5: 2.85625 | BH5: 2.85625 | BI5: 2.85625 | BJ5: 2.85625 | BK5: 4.4375 | BL5: 4.4375 | BM5: 4.4375 | BN5: 4.4375 | BO5: 4.4375 | BP5: 7.2 | BQ5: 7.2 | BR5: 7.2 | BS5: 7.2 | BT5: 7.2 | BU5: 12.15 | BV5: 12.15 | BW5: 12.15 | BX5: 12.15 | BY5: 12.15 | BZ5: 22.90625 | CA5: 22.90625 | CB5: 22.90625 | CC5: 22.90625 | CD5: 22.90625 | CE5: 43.20625 | CF5: 43.20625 | CG5: 43.20625 | CH5: 43.20625 | CI5: 43.20625 | CJ5: 78.55 | CK5: 78.55 | CL5: 78.55 | CM5: 78.55 | CN5: 78.55 | CO5: 154.11875 | CP5: 154.11875 | CQ5: 154.11875 | CR5: 154.11875 | CS5: 154.11875 | CT5: 154.11875 | CU5: 154.11875 | CV5: 154.11875 | CW5: 154.11875 | CX5: 154.11875 | CY5: 154.11875
A8: fertility rate[age] | B8: 0 | C8: 0 | D8: 0 | E8: 0 | F8: 0 | G8: 0 | H8: 0 | I8: 0 | J8: 0 | K8: 0 | L8: 0 | M8: 0 | N8: 0 | O8: 0 | P8: 0 | Q8: 0 | R8: 2.89375 | S8: 2.89375 | T8: 2.89375 | U8: 2.89375 | V8: 2.89375 | W8: 15.60625 | X8: 15.60625 | Y8: 15.60625 | Z8: 15.60625 | AA8: 15.60625 | AB8: 59.85625 | AC8: 59.85625 | AD8: 59.85625 | AE8: 59.85625 | AF8: 59.85625 | AG8: 89.74375 | AH8: 89.74375 | AI8: 89.74375 | AJ8: 89.74375 | AK8: 89.74375 | AL8: 47.90625 | AM8: 47.90625 | AN8: 47.90625 | AO8: 47.90625 | AP8: 47.90625 | AQ8: 8.8625 | AR8: 8.8625 | AS8: 8.8625 | AT8: 8.8625 | AU8: 8.8625 | AV8: 0.4125 | AW8: 0.4125 | AX8: 0.4125 | AY8: 0.4125 | AZ8: 0.4125 | BA8: 0 | BB8: 0 | BC8: 0 | BD8: 0 | BE8: 0 | BF8: 0 | BG8: 0 | BH8: 0 | BI8: 0 | BJ8: 0 | BK8: 0 | BL8: 0 | BM8: 0 | BN8: 0 | BO8: 0 | BP8: 0 | BQ8: 0 | BR8: 0 | BS8: 0 | BT8: 0 | BU8: 0 | BV8: 0 | BW8: 0 | BX8: 0 | BY8: 0 | BZ8: 0 | CA8: 0 | CB8: 0 | CC8: 0 | CD8: 0 | CE8: 0 | CF8: 0 | CG8: 0 | CH8: 0 | CI8: 0 | CJ8: 0 | CK8: 0 | CL8: 0 | CM8: 0 | CN8: 0 | CO8: 0 | CP8: 0 | CQ8: 0 | CR8: 0 | CS8: 0 | CT8: 0 | CU8: 0 | CV8: 0 | CW8: 0 | CX8: 0 | CY8: 0
B10: Male | C10: Female
A11: gender proportion of babies[gender] | B11: 0.48 | C11: 0.52
A13: Resident population initial values | B13: NewBorn | C13: Age00 | D13: Age01 | E13: Age02 | F13: Age03 | G13: Age04 | H13: Age05 | I13: Age06 | J13: Age07 | K13: Age08 | L13: Age09 | M13: Age10 | N13: Age11 | O13: Age12 | P13: Age13 | Q13: Age14 | R13: Age15 | S13: Age16 | T13: Age17 | U13: Age18 | V13: Age19 | W13: Age20 | X13: Age21 | Y13: Age22 | Z13: Age23 | AA13: Age24 | AB13: Age25 | AC13: Age26 | AD13: Age27 | AE13: Age28 | AF13: Age29 | AG13: Age30 | AH13: Age31 | AI13: Age32 | AJ13: Age33 | AK13: Age34 | AL13: Age35 | AM13: Age36 | AN13: Age37 | AO13: Age38 | AP13: Age39 | AQ13: Age40 | AR13: Age41 | AS13: Age42 | AT13: Age43 | AU13: Age44 | AV13: Age45 | AW13: Age46 | AX13: Age47 | AY13: Age48 | AZ13: Age49 | BA13: Age50 | BB13: Age51 | BC13: Age52 | BD13: Age53 | BE13: Age54 | BF13: Age55 | BG13: Age56 | BH13: Age57 | BI13: Age58 | BJ13: Age59 | BK13: Age60 | BL13: Age61 | BM13: Age62 | BN13: Age63 | BO13: Age64 | BP13: Age65 | BQ13: Age66 | BR13: Age67 | BS13: Age68 | BT13: Age69 | BU13: Age70 | BV13: Age71 | BW13: Age72 | BX13: Age73 | BY13: Age74 | BZ13: Age75 | CA13: Age76 | CB13: Age77 | CC13: Age78 | CD13: Age79 | CE13: Age80 | CF13: Age81 | CG13: Age82 | CH13: Age83 | CI13: Age84 | CJ13: Age85 | CK13: Age86 | CL13: Age87 | CM13: Age88 | CN13: Age89 | CO13: Age90 | CP13: Age91 | CQ13: Age92 | CR13: Age93 | CS13: Age94 | CT13: Age95 | CU13: Age96 | CV13: Age97 | CW13: Age98 | CX13: Age99 | CY13: Age100and Over
A14: resident population[Chinese, male, age] | B14: 0 | C14: 11690 | D14: 13107 | E14: 13950 | F14: 13455 | G14: 13487 | H14: 13571 | I14: 13356 | J14: 14338 | K14: 14505 | L14: 17005 | M14: 16697 | N14: 15834 | O14: 17430 | P14: 18070 | Q14: 18586 | R14: 18931 | S14: 19051 | T14: 19018 | U14: 18352 | V14: 19485 | W14: 18320 | X14: 20385 | Y14: 18161 | Z14: 15176 | AA14: 16447 | AB14: 17921 | AC14: 17645 | AD14: 19421 | AE14: 20061 | AF14: 19949 | AG14: 20134 | AH14: 20515 | AI14: 19805 | AJ14: 21675 | AK14: 20834 | AL14: 20944 | AM14: 22355 | AN14: 23515 | AO14: 22760 | AP14: 22362 | AQ14: 21187 | AR14: 20958 | AS14: 22171 | AT14: 22038 | AU14: 23786 | AV14: 23840 | AW14: 24638 | AX14: 24439 | AY14: 23844 | AZ14: 24238 | BA14: 24103 | BB14: 24187 | BC14: 23577 | BD14: 23634 | BE14: 22634 | BF14: 21785 | BG14: 21675 | BH14: 20195 | BI14: 19017 | BJ14: 18028 | BK14: 17950 | BL14: 17426 | BM14: 16157 | BN14: 15756 | BO14: 10845 | BP14: 8246 | BQ14: 10067 | BR14: 8737 | BS14: 8412 | BT14: 9557 | BU14: 9180 | BV14: 8616 | BW14: 6932 | BX14: 5621 | BY14: 5579 | BZ14: 5823 | CA14: 4989 | CB14: 4479 | CC14: 4093 | CD14: 3593 | CE14: 3222 | CF14: 2843 | CG14: 2371 | CH14: 2108 | CI14: 1639 | CJ14: 1394 | CK14: 1157 | CL14: 989 | CM14: 801 | CN14: 693 | CO14: 542 | CP14: 432 | CQ14: 357 | CR14: 276 | CS14: 193 | CT14: 174 | CU14: 120 | CV14: 88 | CW14: 79 | CX14: 67 | CY14: 203
A15: resident population[Chinese, female, age] | B15: 0 | C15: 11185 | D15: 12384 | E15: 13323 | F15: 12864 | G15: 12868 | H15: 13017 | I15: 12598 | J15: 13749 | K15: 13769 | L15: 15956 | M15: 15514 | N15: 14790 | O15: 16486 | P15: 16984 | Q15: 17635 | R15: 17837 | S15: 18448 | T15: 17940 | U15: 18052 | V15: 19025 | W15: 17704 | X15: 20184 | Y15: 17837 | Z15: 15012 | AA15: 16495 | AB15: 18214 | AC15: 18512 | AD15: 20599 | AE15: 21441 | AF15: 21808 | AG15: 21914 | AH15: 22664 | AI15: 22086 | AJ15: 24153 | AK15: 22899 | AL15: 23075 | AM15: 24651 | AN15: 25686 | AO15: 24861 | AP15: 24551 | AQ15: 23386 | AR15: 23104 | AS15: 23577 | AT15: 22871 | AU15: 24255 | AV15: 23859 | AW15: 24781 | AX15: 24285 | AY15: 23825 | AZ15: 23812 | BA15: 23940 | BB15: 23963 | BC15: 23559 | BD15: 23628 | BE15: 22693 | BF15: 21867 | BG15: 21018 | BH15: 19889 | BI15: 19097 | BJ15: 18006 | BK15: 18164 | BL15: 17480 | BM15: 16789 | BN15: 16480 | BO15: 11286 | BP15: 8727 | BQ15: 10866 | BR15: 9102 | BS15: 9420 | BT15: 10901 | BU15: 10600 | BV15: 10107 | BW15: 7923 | BX15: 6421 | BY15: 6368 | BZ15: 7385 | CA15: 6493 | CB15: 5913 | CC15: 5605 | CD15: 5138 | CE15: 4929 | CF15: 4737 | CG15: 4232 | CH15: 3762 | CI15: 3205 | CJ15: 2595 | CK15: 2384 | CL15: 2188 | CM15: 1861 | CN15: 1610 | CO15: 1405 | CP15: 1142 | CQ15: 985 | CR15: 791 | CS15: 631 | CT15: 503 | CU15: 392 | CV15: 343 | CW15: 235 | CX15: 168 | CY15: 446
A16: resident population[Malay, male, age] | B16: 0 | C16: 3016 | D16: 3261 | E16: 3308 | F16: 3458 | G16: 3453 | H16: 3440 | I16: 3484 | J16: 3725 | K16: 4089 | L16: 4322 | M16: 4246 | N16: 4489 | O16: 4484 | P16: 4593 | Q16: 4710 | R16: 4781 | S16: 5098 | T16: 5044 | U16: 4937 | V16: 5210 | W16: 5001 | X16: 4811 | Y16: 4588 | Z16: 4053 | AA16: 4204 | AB16: 4025 | AC16: 3816 | AD16: 3902 | AE16: 3638 | AF16: 3514 | AG16: 3159 | AH16: 2849 | AI16: 2801 | AJ16: 2766 | AK16: 2764 | AL16: 3079 | AM16: 3090 | AN16: 3456 | AO16: 3295 | AP16: 3227 | AQ16: 3004 | AR16: 3332 | AS16: 3800 | AT16: 4053 | AU16: 4306 | AV16: 4290 | AW16: 4614 | AX16: 4405 | AY16: 4453 | AZ16: 4326 | BA16: 4252 | BB16: 4009 | BC16: 3804 | BD16: 3545 | BE16: 3355 | BF16: 3172 | BG16: 3097 | BH16: 2642 | BI16: 2343 | BJ16: 2143 | BK16: 2104 | BL16: 1907 | BM16: 1861 | BN16: 1945 | BO16: 1114 | BP16: 845 | BQ16: 1059 | BR16: 782 | BS16: 734 | BT16: 917 | BU16: 932 | BV16: 892 | BW16: 773 | BX16: 705 | BY16: 681 | BZ16: 802 | CA16: 634 | CB16: 555 | CC16: 434 | CD16: 379 | CE16: 407 | CF16: 405 | CG16: 347 | CH16: 310 | CI16: 237 | CJ16: 211 | CK16: 158 | CL16: 149 | CM16: 136 | CN16: 71 | CO16: 71 | CP16: 50 | CQ16: 50 | CR16: 40 | CS16: 14 | CT16: 6 | CU16: 7 | CV16: 7 | CW16: 8 | CX16: 3 | CY16: 12
A17: resident population[Malay, female, age] | B17: 0 | C17: 2906 | D17: 3096 | E17: 3260 | F17: 3159 | G17: 3286 | H17: 3233 | I17: 3416 | J17: 3534 | K17: 3723 | L17: 3912 | M17: 4111 | N17: 3951 | O17: 4357 | P17: 4258 | Q17: 4390 | R17: 4508 | S17: 4713 | T17: 4732 | U17: 4866 | V17: 4738 | W17: 4897 | X17: 4567 | Y17: 4361 | Z17: 4034 | AA17: 3993 | AB17: 4005 | AC17: 3732 | AD17: 3851 | AE17: 3590 | AF17: 3580 | AG17: 3241 | AH17: 3157 | AI17: 3058 | AJ17: 2967 | AK17: 3045 | AL17: 3225 | AM17: 3315 | AN17: 3523 | AO17: 3526 | AP17: 3463 | AQ17: 3248 | AR17: 3609 | AS17: 3798 | AT17: 4299 | AU17: 4520 | AV17: 4473 | AW17: 4630 | AX17: 4462 | AY17: 4433 | AZ17: 4331 | BA17: 4186 | BB17: 3965 | BC17: 3828 | BD17: 3559 | BE17: 3433 | BF17: 3268 | BG17: 3108 | BH17: 2807 | BI17: 2625 | BJ17: 2330 | BK17: 2325 | BL17: 2081 | BM17: 2039 | BN17: 2053 | BO17: 1179 | BP17: 991 | BQ17: 1244 | BR17: 1009 | BS17: 973 | BT17: 1108 | BU17: 1112 | BV17: 1129 | BW17: 922 | BX17: 680 | BY17: 888 | BZ17: 1117 | CA17: 953 | CB17: 740 | CC17: 637 | CD17: 501 | CE17: 536 | CF17: 472 | CG17: 426 | CH17: 376 | CI17: 201 | CJ17: 230 | CK17: 164 | CL17: 179 | CM17: 163 | CN17: 76 | CO17: 66 | CP17: 54 | CQ17: 55 | CR17: 40 | CS17: 10 | CT17: 13 | CU17: 10 | CV17: 14 | CW17: 12 | CX17: 4 | CY17: 10
A18: resident population[Indian, male, age] | B18: 0 | C18: 1447 | D18: 2236 | E18: 2739 | F18: 2874 | G18: 2820 | H18: 2698 | I18: 2782 | J18: 2634 | K18: 2630 | L18: 2569 | M18: 2581 | N18: 2434 | O18: 2388 | P18: 2326 | Q18: 2291 | R18: 2301 | S18: 2311 | T18: 2336 | U18: 2176 | V18: 2190 | W18: 2171 | X18: 2158 | Y18: 2120 | Z18: 2101 | AA18: 2071 | AB18: 2186 | AC18: 2314 | AD18: 2680 | AE18: 3037 | AF18: 3364 | AG18: 3554 | AH18: 3665 | AI18: 3806 | AJ18: 4055 | AK18: 3910 | AL18: 4195 | AM18: 4027 | AN18: 4034 | AO18: 4132 | AP18: 3911 | AQ18: 3636 | AR18: 3564 | AS18: 3412 | AT18: 3433 | AU18: 3337 | AV18: 3146 | AW18: 3140 | AX18: 2864 | AY18: 2776 | AZ18: 2773 | BA18: 2743 | BB18: 2556 | BC18: 2390 | BD18: 2133 | BE18: 2106 | BF18: 1848 | BG18: 1757 | BH18: 1745 | BI18: 1541 | BJ18: 1369 | BK18: 1451 | BL18: 1284 | BM18: 1247 | BN18: 1212 | BO18: 734 | BP18: 613 | BQ18: 653 | BR18: 573 | BS18: 655 | BT18: 638 | BU18: 656 | BV18: 504 | BW18: 434 | BX18: 390 | BY18: 398 | BZ18: 418 | CA18: 398 | CB18: 439 | CC18: 410 | CD18: 378 | CE18: 369 | CF18: 328 | CG18: 257 | CH18: 228 | CI18: 224 | CJ18: 181 | CK18: 149 | CL18: 99 | CM18: 93 | CN18: 60 | CO18: 54 | CP18: 57 | CQ18: 44 | CR18: 32 | CS18: 35 | CT18: 23 | CU18: 17 | CV18: 9 | CW18: 19 | CX18: 4 | CY18: 37
A19: resident population[Indian, female, age] | B19: 0 | C19: 1480 | D19: 2274 | E19: 2812 | F19: 2888 | G19: 2855 | H19: 2812 | I19: 2697 | J19: 2668 | K19: 2571 | L19: 2494 | M19: 2416 | N19: 2458 | O19: 2421 | P19: 2339 | Q19: 2292 | R19: 2265 | S19: 2357 | T19: 2273 | U19: 2293 | V19: 2267 | W19: 2192 | X19: 2154 | Y19: 2265 | Z19: 2168 | AA19: 2288 | AB19: 2683 | AC19: 2797 | AD19: 3236 | AE19: 3366 | AF19: 3663 | AG19: 3778 | AH19: 3553 | AI19: 3414 | AJ19: 3396 | AK19: 3284 | AL19: 3198 | AM19: 3089 | AN19: 2962 | AO19: 2840 | AP19: 2697 | AQ19: 2547 | AR19: 2529 | AS19: 2502 | AT19: 2545 | AU19: 2588 | AV19: 2533 | AW19: 2594 | AX19: 2555 | AY19: 2448 | AZ19: 2422 | BA19: 2363 | BB19: 2152 | BC19: 2100 | BD19: 1965 | BE19: 1935 | BF19: 1848 | BG19: 1697 | BH19: 1544 | BI19: 1540 | BJ19: 1419 | BK19: 1449 | BL19: 1390 | BM19: 1220 | BN19: 1273 | BO19: 749 | BP19: 648 | BQ19: 653 | BR19: 603 | BS19: 674 | BT19: 666 | BU19: 714 | BV19: 657 | BW19: 592 | BX19: 515 | BY19: 514 | BZ19: 531 | CA19: 423 | CB19: 403 | CC19: 358 | CD19: 289 | CE19: 309 | CF19: 251 | CG19: 236 | CH19: 185 | CI19: 128 | CJ19: 121 | CK19: 98 | CL19: 100 | CM19: 64 | CN19: 46 | CO19: 36 | CP19: 30 | CQ19: 22 | CR19: 23 | CS19: 7 | CT19: 6 | CU19: 6 | CV19: 5 | CW19: 8 | CX19: 2 | CY19: 7
A20: resident population[Other, male, age] | B20: 0 | C20: 540 | D20: 945 | E20: 1052 | F20: 1066 | G20: 986 | H20: 1046 | I20: 1076 | J20: 997 | K20: 974 | L20: 974 | M20: 939 | N20: 861 | O20: 836 | P20: 768 | Q20: 708 | R20: 653 | S20: 584 | T20: 552 | U20: 488 | V20: 505 | W20: 458 | X20: 466 | Y20: 420 | Z20: 390 | AA20: 441 | AB20: 531 | AC20: 623 | AD20: 667 | AE20: 928 | AF20: 1077 | AG20: 1249 | AH20: 1263 | AI20: 1294 | AJ20: 1457 | AK20: 1493 | AL20: 1559 | AM20: 1549 | AN20: 1654 | AO20: 1618 | AP20: 1556 | AQ20: 1549 | AR20: 1307 | AS20: 1445 | AT20: 1338 | AU20: 1339 | AV20: 1219 | AW20: 1158 | AX20: 1131 | AY20: 1009 | AZ20: 934 | BA20: 873 | BB20: 770 | BC20: 743 | BD20: 669 | BE20: 638 | BF20: 580 | BG20: 533 | BH20: 483 | BI20: 439 | BJ20: 430 | BK20: 442 | BL20: 368 | BM20: 389 | BN20: 372 | BO20: 232 | BP20: 199 | BQ20: 184 | BR20: 169 | BS20: 139 | BT20: 142 | BU20: 153 | BV20: 119 | BW20: 118 | BX20: 106 | BY20: 98 | BZ20: 80 | CA20: 83 | CB20: 85 | CC20: 68 | CD20: 74 | CE20: 67 | CF20: 59 | CG20: 39 | CH20: 40 | CI20: 32 | CJ20: 31 | CK20: 26 | CL20: 18 | CM20: 19 | CN20: 11 | CO20: 8 | CP20: 11 | CQ20: 7 | CR20: 2 | CS20: 4 | CT20: 1 | CU20: 2 | CV20: 1 | CW20: 2 | CX20: 2 | CY20: 6
A21: resident population[Other, female, age] | B21: 0 | C21: 524 | D21: 1047 | E21: 1118 | F21: 1105 | G21: 1108 | H21: 1098 | I21: 1063 | J21: 1053 | K21: 1030 | L21: 1067 | M21: 961 | N21: 1004 | O21: 962 | P21: 878 | Q21: 824 | R21: 750 | S21: 670 | T21: 687 | U21: 714 | V21: 612 | W21: 550 | X21: 608 | Y21: 628 | Z21: 612 | AA21: 699 | AB21: 883 | AC21: 1079 | AD21: 1235 | AE21: 1410 | AF21: 1656 | AG21: 1685 | AH21: 1820 | AI21: 1803 | AJ21: 1905 | AK21: 1817 | AL21: 1894 | AM21: 1847 | AN21: 1804 | AO21: 1764 | AP21: 1735 | AQ21: 1637 | AR21: 1518 | AS21: 1350 | AT21: 1369 | AU21: 1194 | AV21: 1088 | AW21: 1041 | AX21: 946 | AY21: 864 | AZ21: 840 | BA21: 781 | BB21: 669 | BC21: 581 | BD21: 551 | BE21: 472 | BF21: 456 | BG21: 395 | BH21: 367 | BI21: 328 | BJ21: 265 | BK21: 310 | BL21: 261 | BM21: 266 | BN21: 258 | BO21: 147 | BP21: 108 | BQ21: 108 | BR21: 135 | BS21: 124 | BT21: 130 | BU21: 131 | BV21: 122 | BW21: 104 | BX21: 118 | BY21: 114 | BZ21: 107 | CA21: 104 | CB21: 86 | CC21: 77 | CD21: 104 | CE21: 74 | CF21: 77 | CG21: 70 | CH21: 65 | CI21: 36 | CJ21: 31 | CK21: 35 | CL21: 31 | CM21: 34 | CN21: 25 | CO21: 20 | CP21: 16 | CQ21: 14 | CR21: 8 | CS21: 10 | CT21: 7 | CU21: 10 | CV21: 4 | CW21: 7 | CX21: 4 | CY21: 3
A23: Net migration rate | B23: NewBorn | C23: Age00 | D23: Age01 | E23: Age02 | F23: Age03 | G23: Age04 | H23: Age05 | I23: Age06 | J23: Age07 | K23: Age08 | L23: Age09 | M23: Age10 | N23: Age11 | O23: Age12 | P23: Age13 | Q23: Age14 | R23: Age15 | S23: Age16 | T23: Age17 | U23: Age18 | V23: Age19 | W23: Age20 | X23: Age21 | Y23: Age22 | Z23: Age23 | AA23: Age24 | AB23: Age25 | AC23: Age26 | AD23: Age27 | AE23: Age28 | AF23: Age29 | AG23: Age30 | AH23: Age31 | AI23: Age32 | AJ23: Age33 | AK23: Age34 | AL23: Age35 | AM23: Age36 | AN23: Age37 | AO23: Age38 | AP23: Age39 | AQ23: Age40 | AR23: Age41 | AS23: Age42 | AT23: Age43 | AU23: Age44 | AV23: Age45 | AW23: Age46 | AX23: Age47 | AY23: Age48 | AZ23: Age49 | BA23: Age50 | BB23: Age51 | BC23: Age52 | BD23: Age53 | BE23: Age54 | BF23: Age55 | BG23: Age56 | BH23: Age57 | BI23: Age58 | BJ23: Age59 | BK23: Age60 | BL23: Age61 | BM23: Age62 | BN23: Age63 | BO23: Age64 | BP23: Age65 | BQ23: Age66 | BR23: Age67 | BS23: Age68 | BT23: Age69 | BU23: Age70 | BV23: Age71 | BW23: Age72 | BX23: Age73 | BY23: Age74 | BZ23: Age75 | CA23: Age76 | CB23: Age77 | CC23: Age78 | CD23: Age79 | CE23: Age80 | CF23: Age81 | CG23: Age82 | CH23: Age83 | CI23: Age84 | CJ23: Age85 | CK23: Age86 | CL23: Age87 | CM23: Age88 | CN23: Age89 | CO23: Age90 | CP23: Age91 | CQ23: Age92 | CR23: Age93 | CS23: Age94 | CT23: Age95 | CU23: Age96 | CV23: Age97 | CW23: Age98 | CX23: Age99 | CY23: Age100and Over
A24: net migration rate[Chinese, male, age] | B24: 0 | C24: 0.0059 | D24: =C24 -> 0.0059 | E24: =D24 -> 0.0059 | F24: =E24 -> 0.0059 | G24: =F24 -> 0.0059 | H24: =G24 -> 0.0059 | I24: =H24 -> 0.0059 | J24: =I24 -> 0.0059 | K24: =J24 -> 0.0059 | ... T24: =S24 -> 0.0059 | U24: 0.0059 | V24: =U24 -> 0.0059 | W24: =V24 -> 0.0059 | X24: =W24 -> 0.0059 | Y24: =X24 -> 0.0059 | Z24: =Y24 -> 0.0059 | AA24: =Z24 -> 0.0059 | AB24: =AA24 -> 0.0059 | AC24: =AB24 -> 0.0059 | ... AZ24: =AY24 -> 0.0059 | BA24: 0 | BB24: =BA24 -> 0 | BC24: =BB24 -> 0 | BD24: =BC24 -> 0 | BE24: =BD24 -> 0 | BF24: =BE24 -> 0 | BG24: =BF24 -> 0 | BH24: =BG24 -> 0 | BI24: =BH24 -> 0 | BJ24: =BI24 -> 0 | BK24: 0 | BL24: =BK24 -> 0 | BM24: =BL24 -> 0 | BN24: =BM24 -> 0 | BO24: =BN24 -> 0 | BP24: =BO24 -> 0 | BQ24: =BP24 -> 0 | BR24: =BQ24 -> 0 | BS24: =BR24 -> 0 | ... CY24: =CX24 -> 0
A25: net migration rate[Chinese, female, age] | B25: 0 | C25: =C24 -> 0.0059 | D25: =D24 -> 0.0059 | E25: =E24 -> 0.0059 | F25: =F24 -> 0.0059 | G25: =G24 -> 0.0059 | H25: =H24 -> 0.0059 | I25: =I24 -> 0.0059 | J25: =J24 -> 0.0059 | ... U25: =U24 -> 0.0059 | V25: =U25 -> 0.0059 | W25: =V25 -> 0.0059 | X25: =W25 -> 0.0059 | Y25: =X25 -> 0.0059 | Z25: =Y25 -> 0.0059 | AA25: =Z25 -> 0.0059 | AB25: =AA25 -> 0.0059 | AC25: =AB25 -> 0.0059 | ... AZ25: =AY25 -> 0.0059 | BA25: 0 | BB25: =BA25 -> 0 | BC25: =BB25 -> 0 | BD25: =BC25 -> 0 | BE25: =BD25 -> 0 | BF25: =BE25 -> 0 | BG25: =BF25 -> 0 | BH25: =BG25 -> 0 | BI25: =BH25 -> 0 | BJ25: =BI25 -> 0 | BK25: =BK24 -> 0 | BL25: =BL24 -> 0 | BM25: =BM24 -> 0 | BN25: =BN24 -> 0 | BO25: =BO24 -> 0 | BP25: =BP24 -> 0 | BQ25: =BQ24 -> 0 | BR25: =BR24 -> 0 | ... CY25: =CY24 -> 0
A26: net migration rate[Malay, male, age] | B26: 0 | C26: =C25 -> 0.0059 | D26: =D25 -> 0.0059 | E26: =E25 -> 0.0059 | F26: =F25 -> 0.0059 | G26: =G25 -> 0.0059 | H26: =H25 -> 0.0059 | I26: =I25 -> 0.0059 | J26: =J25 -> 0.0059 | ... U26: =U25 -> 0.0059 | V26: =U26 -> 0.0059 | W26: =V26 -> 0.0059 | X26: =W26 -> 0.0059 | Y26: =X26 -> 0.0059 | Z26: =Y26 -> 0.0059 | AA26: =Z26 -> 0.0059 | AB26: =AA26 -> 0.0059 | AC26: =AB26 -> 0.0059 | ... AZ26: =AY26 -> 0.0059 | BA26: 0 | BB26: =BA26 -> 0 | BC26: =BB26 -> 0 | BD26: =BC26 -> 0 | BE26: =BD26 -> 0 | BF26: =BE26 -> 0 | BG26: =BF26 -> 0 | BH26: =BG26 -> 0 | BI26: =BH26 -> 0 | BJ26: =BI26 -> 0 | BK26: =BK25 -> 0 | BL26: =BL25 -> 0 | BM26: =BM25 -> 0 | BN26: =BN25 -> 0 | BO26: =BO25 -> 0 | BP26: =BP25 -> 0 | BQ26: =BQ25 -> 0 | BR26: =BR25 -> 0 | ... CY26: =CY25 -> 0
A27: net migration rate[Malay, female, age] | B27: 0 | C27: =C26 -> 0.0059 | D27: =D26 -> 0.0059 | E27: =E26 -> 0.0059 | F27: =F26 -> 0.0059 | G27: =G26 -> 0.0059 | H27: =H26 -> 0.0059 | I27: =I26 -> 0.0059 | J27: =J26 -> 0.0059 | ... U27: =U26 -> 0.0059 | V27: =U27 -> 0.0059 | W27: =V27 -> 0.0059 | X27: =W27 -> 0.0059 | Y27: =X27 -> 0.0059 | Z27: =Y27 -> 0.0059 | AA27: =Z27 -> 0.0059 | AB27: =AA27 -> 0.0059 | AC27: =AB27 -> 0.0059 | ... AZ27: =AY27 -> 0.0059 | BA27: 0 | BB27: =BA27 -> 0 | BC27: =BB27 -> 0 | BD27: =BC27 -> 0 | BE27: =BD27 -> 0 | BF27: =BE27 -> 0 | BG27: =BF27 -> 0 | BH27: =BG27 -> 0 | BI27: =BH27 -> 0 | BJ27: =BI27 -> 0 | BK27: =BK26 -> 0 | BL27: =BL26 -> 0 | BM27: =BM26 -> 0 | BN27: =BN26 -> 0 | BO27: =BO26 -> 0 | BP27: =BP26 -> 0 | BQ27: =BQ26 -> 0 | BR27: =BR26 -> 0 | ... CY27: =CY26 -> 0
A28: net migration rate[Indian, male, age] | B28: 0 | C28: =C27 -> 0.0059 | D28: =D27 -> 0.0059 | E28: =E27 -> 0.0059 | F28: =F27 -> 0.0059 | G28: =G27 -> 0.0059 | H28: =H27 -> 0.0059 | I28: =I27 -> 0.0059 | J28: =J27 -> 0.0059 | ... U28: =U27 -> 0.0059 | V28: =U28 -> 0.0059 | W28: =V28 -> 0.0059 | X28: =W28 -> 0.0059 | Y28: =X28 -> 0.0059 | Z28: =Y28 -> 0.0059 | AA28: =Z28 -> 0.0059 | AB28: =AA28 -> 0.0059 | AC28: =AB28 -> 0.0059 | ... AZ28: =AY28 -> 0.0059 | BA28: 0 | BB28: =BA28 -> 0 | BC28: =BB28 -> 0 | BD28: =BC28 -> 0 | BE28: =BD28 -> 0 | BF28: =BE28 -> 0 | BG28: =BF28 -> 0 | BH28: =BG28 -> 0 | BI28: =BH28 -> 0 | BJ28: =BI28 -> 0 | BK28: =BK27 -> 0 | BL28: =BL27 -> 0 | BM28: =BM27 -> 0 | BN28: =BN27 -> 0 | BO28: =BO27 -> 0 | BP28: =BP27 -> 0 | BQ28: =BQ27 -> 0 | BR28: =BR27 -> 0 | ... CY28: =CY27 -> 0
A29: net migration rate[Indian, female, age] | B29: 0 | C29: =C28 -> 0.0059 | D29: =D28 -> 0.0059 | E29: =E28 -> 0.0059 | F29: =F28 -> 0.0059 | G29: =G28 -> 0.0059 | H29: =H28 -> 0.0059 | I29: =I28 -> 0.0059 | J29: =J28 -> 0.0059 | ... U29: =U28 -> 0.0059 | V29: =U29 -> 0.0059 | W29: =V29 -> 0.0059 | X29: =W29 -> 0.0059 | Y29: =X29 -> 0.0059 | Z29: =Y29 -> 0.0059 | AA29: =Z29 -> 0.0059 | AB29: =AA29 -> 0.0059 | AC29: =AB29 -> 0.0059 | ... AZ29: =AY29 -> 0.0059 | BA29: 0 | BB29: =BA29 -> 0 | BC29: =BB29 -> 0 | BD29: =BC29 -> 0 | BE29: =BD29 -> 0 | BF29: =BE29 -> 0 | BG29: =BF29 -> 0 | BH29: =BG29 -> 0 | BI29: =BH29 -> 0 | BJ29: =BI29 -> 0 | BK29: =BK28 -> 0 | BL29: =BL28 -> 0 | BM29: =BM28 -> 0 | BN29: =BN28 -> 0 | BO29: =BO28 -> 0 | BP29: =BP28 -> 0 | BQ29: =BQ28 -> 0 | BR29: =BR28 -> 0 | ... CY29: =CY28 -> 0
A30: net migration rate[Other, male, age] | B30: 0 | C30: =C29 -> 0.0059 | D30: =D29 -> 0.0059 | E30: =E29 -> 0.0059 | F30: =F29 -> 0.0059 | G30: =G29 -> 0.0059 | H30: =H29 -> 0.0059 | I30: =I29 -> 0.0059 | J30: =J29 -> 0.0059 | ... U30: =U29 -> 0.0059 | V30: =U30 -> 0.0059 | W30: =V30 -> 0.0059 | X30: =W30 -> 0.0059 | Y30: =X30 -> 0.0059 | Z30: =Y30 -> 0.0059 | AA30: =Z30 -> 0.0059 | AB30: =AA30 -> 0.0059 | AC30: =AB30 -> 0.0059 | ... AZ30: =AY30 -> 0.0059 | BA30: 0 | BB30: =BA30 -> 0 | BC30: =BB30 -> 0 | BD30: =BC30 -> 0 | BE30: =BD30 -> 0 | BF30: =BE30 -> 0 | BG30: =BF30 -> 0 | BH30: =BG30 -> 0 | BI30: =BH30 -> 0 | BJ30: =BI30 -> 0 | BK30: =BK29 -> 0 | BL30: =BL29 -> 0 | BM30: =BM29 -> 0 | BN30: =BN29 -> 0 | BO30: =BO29 -> 0 | BP30: =BP29 -> 0 | BQ30: =BQ29 -> 0 | BR30: =BR29 -> 0 | ... CY30: =CY29 -> 0
A31: net migration rate[Other, female, age] | B31: 0 | C31: =C30 -> 0.0059 | D31: =D30 -> 0.0059 | E31: =E30 -> 0.0059 | F31: =F30 -> 0.0059 | G31: =G30 -> 0.0059 | H31: =H30 -> 0.0059 | I31: =I30 -> 0.0059 | J31: =J30 -> 0.0059 | ... U31: =U30 -> 0.0059 | V31: =U31 -> 0.0059 | W31: =V31 -> 0.0059 | X31: =W31 -> 0.0059 | Y31: =X31 -> 0.0059 | Z31: =Y31 -> 0.0059 | AA31: =Z31 -> 0.0059 | AB31: =AA31 -> 0.0059 | AC31: =AB31 -> 0.0059 | ... AZ31: =AY31 -> 0.0059 | BA31: 0 | BB31: =BA31 -> 0 | BC31: =BB31 -> 0 | BD31: =BC31 -> 0 | BE31: =BD31 -> 0 | BF31: =BE31 -> 0 | BG31: =BF31 -> 0 | BH31: =BG31 -> 0 | BI31: =BH31 -> 0 | BJ31: =BI31 -> 0 | BK31: =BK30 -> 0 | BL31: =BL30 -> 0 | BM31: =BM30 -> 0 | BN31: =BN30 -> 0 | BO31: =BO30 -> 0 | BP31: =BP30 -> 0 | BQ31: =BQ30 -> 0 | BR31: =BR30 -> 0 | ... CY31: =CY30 -> 0
A33: target total resident population | B33: 4500000
A38: Time | B38: 2010 | C38: 2011 | D38: 2012 | E38: 2013 | F38: 2014 | G38: 2015 | H38: 2016 | I38: 2017 | J38: 2018 | K38: 2019 | L38: 2020 | M38: 2021 | N38: 2022 | O38: 2023 | P38: 2024 | Q38: 2025 | R38: 2026 | S38: 2027 | T38: 2028 | U38: 2029 | V38: 2030 | W38: 2031 | X38: 2032 | Y38: 2033 | Z38: 2034 | AA38: 2035 | AB38: 2036 | AC38: 2037 | AD38: 2038 | AE38: 2039 | AF38: 2040 | AG38: 2041 | AH38: 2042 | AI38: 2043 | AJ38: 2044 | AK38: 2045 | AL38: 2046 | AM38: 2047 | AN38: 2048 | AO38: 2049 | AP38: 2050
A39: Resident Population.census total resident population | B39: 3771721 | C39: 3789251 | D39: 3818205 | E39: 3844751 | F39: 3870739 | G39: 3902690 | H39: 3933559 | I39: 3965796 | J39: 3994283 | K39: 4026209 | L39: 4044210 | M39: 3986842 | N39: 4073239 | O39: 4149253 | P39: 4180868 | Q39: 4204515 | R39: 4227250 | S39: 4249300 | T39: 4270650 | U39: 4290650 | V39: 4309450 | W39: 4327000 | X39: 4343050 | Y39: 4358150 | Z39: 4371600 | AA39: 4383350 | AB39: 4394250 | AC39: 4403000 | AD39: 4410700 | AE39: 4417600 | AF39: 4422600
A40: Resident Population.census males per thousand females | B40: 974 | C40: 972 | D40: 970 | E40: 968 | F40: 967 | G40: 965 | H40: 963 | I40: 961 | J40: 959 | K40: 957 | L40: 957 | M40: 960 | N40: 955 | O40: 950 | P40: 948 | Q40: 947
A41: Resident Population.census OADR | B41: 8.2 | C41: 7.9 | D41: 7.4 | E41: 7 | F41: 6.6 | G41: 6.2 | H41: 5.8 | I41: 5.5 | J41: 5.2 | K41: 4.9 | L41: 4.6 | M41: 4.3 | N41: 4.1 | O41: 4 | P41: 3.8 | Q41: 3.6

Sheet 3. Frail population
A1: Module name | B1: Frail Population
B2: ='2 Resident Population'!B3 -> NewBorn | C2: ='2 Resident Population'!C3 -> Age00 | D2: ='2 Resident Population'!D3 -> Age01 | E2: ='2 Resident Population'!E3 -> Age02 | F2: ='2 Resident Population'!F3 -> Age03 | G2: ='2 Resident Population'!G3 -> Age04 | H2: ='2 Resident Population'!H3 -> Age05 | I2: ='2 Resident Population'!I3 -> Age06 | ... CY2: ='2 Resident Population'!CY3 -> Age100and Over
A3: Frail Population.age as a number[age] | B3: 0 | C3: 0 | D3: 1 | E3: 2 | F3: 3 | G3: 4 | H3: 5 | I3: 6 | J3: 7 | K3: 8 | L3: 9 | M3: 10 | N3: 11 | O3: 12 | P3: 13 | Q3: 14 | R3: 15 | S3: 16 | T3: 17 | U3: 18 | V3: 19 | W3: 20 | X3: 21 | Y3: 22 | Z3: 23 | AA3: 24 | AB3: 25 | AC3: 26 | AD3: 27 | AE3: 28 | AF3: 29 | AG3: 30 | AH3: 31 | AI3: 32 | AJ3: 33 | AK3: 34 | AL3: 35 | AM3: 36 | AN3: 37 | AO3: 38 | AP3: 39 | AQ3: 40 | AR3: 41 | AS3: 42 | AT3: 43 | AU3: 44 | AV3: 45 | AW3: 46 | AX3: 47 | AY3: 48 | AZ3: 49 | BA3: 50 | BB3: 51 | BC3: 52 | BD3: 53 | BE3: 54 | BF3: 55 | BG3: 56 | BH3: 57 | BI3: 58 | BJ3: 59 | BK3: 60 | BL3: 61 | BM3: 62 | BN3: 63 | BO3: 64 | BP3: 65 | BQ3: 66 | BR3: 67 | BS3: 68 | BT3: 69 | BU3: 70 | BV3: 71 | BW3: 72 | BX3: 73 | BY3: 74 | BZ3: 75 | CA3: 76 | CB3: 77 | CC3: 78 | CD3: 79 | CE3: 80 | CF3: 81 | CG3: 82 | CH3: 83 | CI3: 84 | CJ3: 85 | CK3: 86 | CL3: 87 | CM3: 88 | CN3: 89 | CO3: 90 | CP3: 91 | CQ3: 92 | CR3: 93 | CS3: 94 | CT3: 95 | CU3: 96 | CV3: 97 | CW3: 98 | CX3: 99 | CY3: 100
A5: Diagnosed initial stocks (two stocks) | B5: NewBorn | C5: Age00 | D5: Age01 | E5: Age02 | F5: Age03 | G5: Age04 | H5: Age05 | I5: Age06 | J5: Age07 | K5: Age08 | L5: Age09 | M5: Age10 | N5: Age11 | O5: Age12 | P5: Age13 | Q5: Age14 | R5: Age15 | S5: Age16 | T5: Age17 | U5: Age18 | V5: Age19 | W5: Age20 | X5: Age21 | Y5: Age22 | Z5: Age23 | AA5: Age24 | AB5: Age25 | AC5: Age26 | AD5: Age27 | AE5: Age28 | AF5: Age29 | AG5: Age30 | AH5: Age31 | AI5: Age32 | AJ5: Age33 | AK5: Age34 | AL5: Age35 | AM5: Age36 | AN5: Age37 | AO5: Age38 | AP5: Age39 | AQ5: Age40 | AR5: Age41 | AS5: Age42 | AT5: Age43 | AU5: Age44 | AV5: Age45 | AW5: Age46 | AX5: Age47 | AY5: Age48 | AZ5: Age49 | BA5: Age50 | BB5: Age51 | BC5: Age52 | BD5: Age53 | BE5: Age54 | BF5: Age55 | BG5: Age56 | BH5: Age57 | BI5: Age58 | BJ5: Age59 | BK5: Age60 | BL5: Age61 | BM5: Age62 | BN5: Age63 | BO5: Age64 | BP5: Age65 | BQ5: Age66 | BR5: Age67 | BS5: Age68 | BT5: Age69 | BU5: Age70 | BV5: Age71 | BW5: Age72 | BX5: Age73 | BY5: Age74 | BZ5: Age75 | CA5: Age76 | CB5: Age77 | CC5: Age78 | CD5: Age79 | CE5: Age80 | CF5: Age81 | CG5: Age82 | CH5: Age83 | CI5: Age84 | CJ5: Age85 | CK5: Age86 | CL5: Age87 | CM5: Age88 | CN5: Age89 | CO5: Age90 | CP5: Age91 | CQ5: Age92 | CR5: Age93 | CS5: Age94 | CT5: Age95 | CU5: Age96 | CV5: Age97 | CW5: Age98 | CX5: Age99 | CY5: Age100and Over
A6: Frail Population.frail diagnosed[Chinese, male, age] | B6: 0 | C6: 0 | D6: 0 | E6: 0 | F6: 0 | G6: 0 | H6: 0 | I6: 0 | J6: 0 | K6: 0 | L6: 0 | M6: 0 | N6: 0 | O6: 0 | P6: 0 | Q6: 0 | R6: 0 | S6: 0 | T6: 0 | U6: 0 | V6: 0 | W6: 0 | X6: 0 | Y6: 0 | Z6: 0 | AA6: 0 | AB6: 0 | AC6: 0 | AD6: 0 | AE6: 0 | AF6: 0 | AG6: 0 | AH6: 0 | AI6: 0 | AJ6: 0 | AK6: 0 | AL6: 0 | AM6: 0 | AN6: 0 | AO6: 0 | AP6: 0 | AQ6: 0 | AR6: 0 | AS6: 0 | AT6: 0 | AU6: 0 | AV6: 0 | AW6: 0 | AX6: 0 | AY6: 0 | AZ6: 0 | BA6: 0 | BB6: 0 | BC6: 0 | BD6: 0 | BE6: 0 | BF6: 0 | BG6: 0 | BH6: 0 | BI6: 0 | BJ6: 0 | BK6: 0 | BL6: 0 | BM6: 0 | BN6: 0 | BO6: 0 | BP6: 0 | BQ6: 0 | BR6: 0 | BS6: 0 | BT6: 0 | BU6: 0 | BV6: 0 | BW6: 0 | BX6: 0 | BY6: 0 | BZ6: 0 | CA6: 0 | CB6: 0 | CC6: 0 | CD6: 0 | CE6: 0 | CF6: 0 | CG6: 0 | CH6: 0 | CI6: 0 | CJ6: 0 | CK6: 0 | CL6: 0 | CM6: 0 | CN6: 0 | CO6: 0 | CP6: 0 | CQ6: 0 | CR6: 0 | CS6: 0 | CT6: 0 | CU6: 0 | CV6: 0 | CW6: 0 | CX6: 0 | CY6: 0
A7: Frail Population.frail diagnosed[Chinese, female, age] | B7: 0 | C7: 0 | D7: 0 | E7: 0 | F7: 0 | G7: 0 | H7: 0 | I7: 0 | J7: 0 | K7: 0 | L7: 0 | M7: 0 | N7: 0 | O7: 0 | P7: 0 | Q7: 0 | R7: 0 | S7: 0 | T7: 0 | U7: 0 | V7: 0 | W7: 0 | X7: 0 | Y7: 0 | Z7: 0 | AA7: 0 | AB7: 0 | AC7: 0 | AD7: 0 | AE7: 0 | AF7: 0 | AG7: 0 | AH7: 0 | AI7: 0 | AJ7: 0 | AK7: 0 | AL7: 0 | AM7: 0 | AN7: 0 | AO7: 0 | AP7: 0 | AQ7: 0 | AR7: 0 | AS7: 0 | AT7: 0 | AU7: 0 | AV7: 0 | AW7: 0 | AX7: 0 | AY7: 0 | AZ7: 0 | BA7: 0 | BB7: 0 | BC7: 0 | BD7: 0 | BE7: 0 | BF7: 0 | BG7: 0 | BH7: 0 | BI7: 0 | BJ7: 0 | BK7: 0 | BL7: 0 | BM7: 0 | BN7: 0 | BO7: 0 | BP7: 0 | BQ7: 0 | BR7: 0 | BS7: 0 | BT7: 0 | BU7: 0 | BV7: 0 | BW7: 0 | BX7: 0 | BY7: 0 | BZ7: 0 | CA7: 0 | CB7: 0 | CC7: 0 | CD7: 0 | CE7: 0 | CF7: 0 | CG7: 0 | CH7: 0 | CI7: 0 | CJ7: 0 | CK7: 0 | CL7: 0 | CM7: 0 | CN7: 0 | CO7: 0 | CP7: 0 | CQ7: 0 | CR7: 0 | CS7: 0 | CT7: 0 | CU7: 0 | CV7: 0 | CW7: 0 | CX7: 0 | CY7: 0
A8: Frail Population.frail diagnosed[Malay, male, age] | B8: 0 | C8: 0 | D8: 0 | E8: 0 | F8: 0 | G8: 0 | H8: 0 | I8: 0 | J8: 0 | K8: 0 | L8: 0 | M8: 0 | N8: 0 | O8: 0 | P8: 0 | Q8: 0 | R8: 0 | S8: 0 | T8: 0 | U8: 0 | V8: 0 | W8: 0 | X8: 0 | Y8: 0 | Z8: 0 | AA8: 0 | AB8: 0 | AC8: 0 | AD8: 0 | AE8: 0 | AF8: 0 | AG8: 0 | AH8: 0 | AI8: 0 | AJ8: 0 | AK8: 0 | AL8: 0 | AM8: 0 | AN8: 0 | AO8: 0 | AP8: 0 | AQ8: 0 | AR8: 0 | AS8: 0 | AT8: 0 | AU8: 0 | AV8: 0 | AW8: 0 | AX8: 0 | AY8: 0 | AZ8: 0 | BA8: 0 | BB8: 0 | BC8: 0 | BD8: 0 | BE8: 0 | BF8: 0 | BG8: 0 | BH8: 0 | BI8: 0 | BJ8: 0 | BK8: 0 | BL8: 0 | BM8: 0 | BN8: 0 | BO8: 0 | BP8: 0 | BQ8: 0 | BR8: 0 | BS8: 0 | BT8: 0 | BU8: 0 | BV8: 0 | BW8: 0 | BX8: 0 | BY8: 0 | BZ8: 0 | CA8: 0 | CB8: 0 | CC8: 0 | CD8: 0 | CE8: 0 | CF8: 0 | CG8: 0 | CH8: 0 | CI8: 0 | CJ8: 0 | CK8: 0 | CL8: 0 | CM8: 0 | CN8: 0 | CO8: 0 | CP8: 0 | CQ8: 0 | CR8: 0 | CS8: 0 | CT8: 0 | CU8: 0 | CV8: 0 | CW8: 0 | CX8: 0 | CY8: 0
A9: Frail Population.frail diagnosed[Malay, female, age] | B9: 0 | C9: 0 | D9: 0 | E9: 0 | F9: 0 | G9: 0 | H9: 0 | I9: 0 | J9: 0 | K9: 0 | L9: 0 | M9: 0 | N9: 0 | O9: 0 | P9: 0 | Q9: 0 | R9: 0 | S9: 0 | T9: 0 | U9: 0 | V9: 0 | W9: 0 | X9: 0 | Y9: 0 | Z9: 0 | AA9: 0 | AB9: 0 | AC9: 0 | AD9: 0 | AE9: 0 | AF9: 0 | AG9: 0 | AH9: 0 | AI9: 0 | AJ9: 0 | AK9: 0 | AL9: 0 | AM9: 0 | AN9: 0 | AO9: 0 | AP9: 0 | AQ9: 0 | AR9: 0 | AS9: 0 | AT9: 0 | AU9: 0 | AV9: 0 | AW9: 0 | AX9: 0 | AY9: 0 | AZ9: 0 | BA9: 0 | BB9: 0 | BC9: 0 | BD9: 0 | BE9: 0 | BF9: 0 | BG9: 0 | BH9: 0 | BI9: 0 | BJ9: 0 | BK9: 0 | BL9: 0 | BM9: 0 | BN9: 0 | BO9: 0 | BP9: 0 | BQ9: 0 | BR9: 0 | BS9: 0 | BT9: 0 | BU9: 0 | BV9: 0 | BW9: 0 | BX9: 0 | BY9: 0 | BZ9: 0 | CA9: 0 | CB9: 0 | CC9: 0 | CD9: 0 | CE9: 0 | CF9: 0 | CG9: 0 | CH9: 0 | CI9: 0 | CJ9: 0 | CK9: 0 | CL9: 0 | CM9: 0 | CN9: 0 | CO9: 0 | CP9: 0 | CQ9: 0 | CR9: 0 | CS9: 0 | CT9: 0 | CU9: 0 | CV9: 0 | CW9: 0 | CX9: 0 | CY9: 0
A10: Frail Population.frail diagnosed[Indian, male, age] | B10: 0 | C10: 0 | D10: 0 | E10: 0 | F10: 0 | G10: 0 | H10: 0 | I10: 0 | J10: 0 | K10: 0 | L10: 0 | M10: 0 | N10: 0 | O10: 0 | P10: 0 | Q10: 0 | R10: 0 | S10: 0 | T10: 0 | U10: 0 | V10: 0 | W10: 0 | X10: 0 | Y10: 0 | Z10: 0 | AA10: 0 | AB10: 0 | AC10: 0 | AD10: 0 | AE10: 0 | AF10: 0 | AG10: 0 | AH10: 0 | AI10: 0 | AJ10: 0 | AK10: 0 | AL10: 0 | AM10: 0 | AN10: 0 | AO10: 0 | AP10: 0 | AQ10: 0 | AR10: 0 | AS10: 0 | AT10: 0 | AU10: 0 | AV10: 0 | AW10: 0 | AX10: 0 | AY10: 0 | AZ10: 0 | BA10: 0 | BB10: 0 | BC10: 0 | BD10: 0 | BE10: 0 | BF10: 0 | BG10: 0 | BH10: 0 | BI10: 0 | BJ10: 0 | BK10: 0 | BL10: 0 | BM10: 0 | BN10: 0 | BO10: 0 | BP10: 0 | BQ10: 0 | BR10: 0 | BS10: 0 | BT10: 0 | BU10: 0 | BV10: 0 | BW10: 0 | BX10: 0 | BY10: 0 | BZ10: 0 | CA10: 0 | CB10: 0 | CC10: 0 | CD10: 0 | CE10: 0 | CF10: 0 | CG10: 0 | CH10: 0 | CI10: 0 | CJ10: 0 | CK10: 0 | CL10: 0 | CM10: 0 | CN10: 0 | CO10: 0 | CP10: 0 | CQ10: 0 | CR10: 0 | CS10: 0 | CT10: 0 | CU10: 0 | CV10: 0 | CW10: 0 | CX10: 0 | CY10: 0
A11: Frail Population.frail diagnosed[Indian, female, age] | B11: 0 | C11: 0 | D11: 0 | E11: 0 | F11: 0 | G11: 0 | H11: 0 | I11: 0 | J11: 0 | K11: 0 | L11: 0 | M11: 0 | N11: 0 | O11: 0 | P11: 0 | Q11: 0 | R11: 0 | S11: 0 | T11: 0 | U11: 0 | V11: 0 | W11: 0 | X11: 0 | Y11: 0 | Z11: 0 | AA11: 0 | AB11: 0 | AC11: 0 | AD11: 0 | AE11: 0 | AF11: 0 | AG11: 0 | AH11: 0 | AI11: 0 | AJ11: 0 | AK11: 0 | AL11: 0 | AM11: 0 | AN11: 0 | AO11: 0 | AP11: 0 | AQ11: 0 | AR11: 0 | AS11: 0 | AT11: 0 | AU11: 0 | AV11: 0 | AW11: 0 | AX11: 0 | AY11: 0 | AZ11: 0 | BA11: 0 | BB11: 0 | BC11: 0 | BD11: 0 | BE11: 0 | BF11: 0 | BG11: 0 | BH11: 0 | BI11: 0 | BJ11: 0 | BK11: 0 | BL11: 0 | BM11: 0 | BN11: 0 | BO11: 0 | BP11: 0 | BQ11: 0 | BR11: 0 | BS11: 0 | BT11: 0 | BU11: 0 | BV11: 0 | BW11: 0 | BX11: 0 | BY11: 0 | BZ11: 0 | CA11: 0 | CB11: 0 | CC11: 0 | CD11: 0 | CE11: 0 | CF11: 0 | CG11: 0 | CH11: 0 | CI11: 0 | CJ11: 0 | CK11: 0 | CL11: 0 | CM11: 0 | CN11: 0 | CO11: 0 | CP11: 0 | CQ11: 0 | CR11: 0 | CS11: 0 | CT11: 0 | CU11: 0 | CV11: 0 | CW11: 0 | CX11: 0 | CY11: 0
A12: Frail Population.frail diagnosed[Other, male, age] | B12: 0 | C12: 0 | D12: 0 | E12: 0 | F12: 0 | G12: 0 | H12: 0 | I12: 0 | J12: 0 | K12: 0 | L12: 0 | M12: 0 | N12: 0 | O12: 0 | P12: 0 | Q12: 0 | R12: 0 | S12: 0 | T12: 0 | U12: 0 | V12: 0 | W12: 0 | X12: 0 | Y12: 0 | Z12: 0 | AA12: 0 | AB12: 0 | AC12: 0 | AD12: 0 | AE12: 0 | AF12: 0 | AG12: 0 | AH12: 0 | AI12: 0 | AJ12: 0 | AK12: 0 | AL12: 0 | AM12: 0 | AN12: 0 | AO12: 0 | AP12: 0 | AQ12: 0 | AR12: 0 | AS12: 0 | AT12: 0 | AU12: 0 | AV12: 0 | AW12: 0 | AX12: 0 | AY12: 0 | AZ12: 0 | BA12: 0 | BB12: 0 | BC12: 0 | BD12: 0 | BE12: 0 | BF12: 0 | BG12: 0 | BH12: 0 | BI12: 0 | BJ12: 0 | BK12: 0 | BL12: 0 | BM12: 0 | BN12: 0 | BO12: 0 | BP12: 0 | BQ12: 0 | BR12: 0 | BS12: 0 | BT12: 0 | BU12: 0 | BV12: 0 | BW12: 0 | BX12: 0 | BY12: 0 | BZ12: 0 | CA12: 0 | CB12: 0 | CC12: 0 | CD12: 0 | CE12: 0 | CF12: 0 | CG12: 0 | CH12: 0 | CI12: 0 | CJ12: 0 | CK12: 0 | CL12: 0 | CM12: 0 | CN12: 0 | CO12: 0 | CP12: 0 | CQ12: 0 | CR12: 0 | CS12: 0 | CT12: 0 | CU12: 0 | CV12: 0 | CW12: 0 | CX12: 0 | CY12: 0
A13: Frail Population.frail diagnosed[Other, female, age] | B13: 0 | C13: 0 | D13: 0 | E13: 0 | F13: 0 | G13: 0 | H13: 0 | I13: 0 | J13: 0 | K13: 0 | L13: 0 | M13: 0 | N13: 0 | O13: 0 | P13: 0 | Q13: 0 | R13: 0 | S13: 0 | T13: 0 | U13: 0 | V13: 0 | W13: 0 | X13: 0 | Y13: 0 | Z13: 0 | AA13: 0 | AB13: 0 | AC13: 0 | AD13: 0 | AE13: 0 | AF13: 0 | AG13: 0 | AH13: 0 | AI13: 0 | AJ13: 0 | AK13: 0 | AL13: 0 | AM13: 0 | AN13: 0 | AO13: 0 | AP13: 0 | AQ13: 0 | AR13: 0 | AS13: 0 | AT13: 0 | AU13: 0 | AV13: 0 | AW13: 0 | AX13: 0 | AY13: 0 | AZ13: 0 | BA13: 0 | BB13: 0 | BC13: 0 | BD13: 0 | BE13: 0 | BF13: 0 | BG13: 0 | BH13: 0 | BI13: 0 | BJ13: 0 | BK13: 0 | BL13: 0 | BM13: 0 | BN13: 0 | BO13: 0 | BP13: 0 | BQ13: 0 | BR13: 0 | BS13: 0 | BT13: 0 | BU13: 0 | BV13: 0 | BW13: 0 | BX13: 0 | BY13: 0 | BZ13: 0 | CA13: 0 | CB13: 0 | CC13: 0 | CD13: 0 | CE13: 0 | CF13: 0 | CG13: 0 | CH13: 0 | CI13: 0 | CJ13: 0 | CK13: 0 | CL13: 0 | CM13: 0 | CN13: 0 | CO13: 0 | CP13: 0 | CQ13: 0 | CR13: 0 | CS13: 0 | CT13: 0 | CU13: 0 | CV13: 0 | CW13: 0 | CX13: 0 | CY13: 0
